Workbook

Sheet Read me
B2: Monid Finance Tools
B5: Scope | C5: 70 retrievable finance tools; 71 advertised. Company/market/news: 55. Insider/ownership: 15. Snapshot 9 September 2026.
B8: Start here | C8: Company tools and Insider tools contain the complete inventory. Provider evidence supplies inherited coverage, provenance, rights and audience. Sources contains primary links.
B11: Cost controls | C11: Edit blue cells in Assumptions and Costs. Profiles are formulas tied to assumptions. Costs shows occasional research and shared regular feeds for 10 and 100 users.
B14: Selected budget | C14: Set Include = 1 for tools you actually want. Default selected budget is zero. Reference totals enable all 70 overlapping tools and are NOT recommended bundles.
B17: Coverage | C17: Website ticker/profile counts do not prove Monid company coverage. Every exact per-tool supported-company count remains unverified.
B20: Permission | C20: No customer-display/storage grant established for these Monid connectors. Paying call charges does not establish news-body/image rights or publisher subscription access.
B23: Freshness | C23: No paid endpoint benchmark, measured error rate or confirmed real-time delivery SLA. SECForm4 public delay does not prove the tier Monid uses.
B26: Scenario limits | C26: One page and one entity per call, no retries by default. Fees exclude licences, tax, infrastructure, AI processing and backfill. Changing scopes/intervals is not proof of API capacity.
B29: Recalculation | C29: Formula cells include cached default results. Excel recalculates when opened/edited. Do not treat saved default results as updated after modifying the file with a non-calculating library.

Sheet Assumptions
A1: Assumption | B1: Editable value | C1: Meaning / limitation
A2: Users: smaller scenario | B2: 10 | C2: Number of app users; not provider seats.
A3: Users: larger scenario | B3: 100 | C3: Number of app users; not provider seats.
A4: Research lookups / user / workday | B4: 5 | C4: Each lookup calls ONE selected endpoint. A multi-tool page sums those endpoint calls.
A5: Workdays / month | B5: 22 | C5: Budget convention, not the actual exchange/filing calendar.
A6: Calendar days / month | B6: 30 | C6: Budget convention.
A7: Followed security keys / user | B7: 20 | C7: A key identifies one security/company query; not necessarily a unique issuer.
A8: Unique-union ratio | B8: 0.5 | C8: Distinct followed keys / sum of watchlist lengths. Sharing requires permission. Minimum is one full watchlist.
A9: Regular market hours / day | B9: 6.5 | C9: US regular-session budget; extended and global sessions require a larger setting.
A10: Market polling interval: minutes | B10: 5 | C10: Proposed polling only; does not establish real-time data.
A11: News active hours / calendar day | B11: 16 | C11: Hourly news monitoring; not 24-hour coverage.
A12: News polling interval: minutes | B12: 60 | C12: Hourly polling. New items can wait up to a polling interval plus upstream lag.
A13: Filing active hours / workday | B13: 16 | C13: Illustrative window, not an exact EDGAR schedule; gaps need catch-up.
... A20: Premarket hours / workday | B20: 5.5 | C20: Illustrative US premarket monitoring window; confirm source session coverage.

Sheet Profiles
A1: Profile key | B1: Proposed cadence | C1: Scope | D1: Polls / key / month
A2: entity_market | B2: Per security: every 5 min in regular market hours | C2: entity | D2: =Assumptions!$B$9*60/Assumptions!$B$10*Assumptions!$B$5 -> 1716
A3: global_market | B3: Shared market list: every 5 min in regular hours | C3: global | D3: =Assumptions!$B$9*60/Assumptions!$B$10*Assumptions!$B$5 -> 1716
A4: entity_news | B4: Per company: hourly, 16 h/day, 30 days | C4: entity | D4: =Assumptions!$B$11*60/Assumptions!$B$12*Assumptions!$B$6 -> 480
A5: entity_hourly | B5: Per company: hourly, 16 h/day, 22 workdays | C5: entity | D5: =Assumptions!$B$13*60/Assumptions!$B$15*Assumptions!$B$5 -> 352
A6: global_insider | B6: Shared disclosure list: 15 min, 16 h, 22 workdays | C6: global | D6: =Assumptions!$B$13*60/Assumptions!$B$14*Assumptions!$B$5 -> 1408
A7: entity_daily | B7: Per company/security: once daily | C7: entity | D7: =Assumptions!$B$16*Assumptions!$B$6 -> 30
A8: global_daily | B8: Shared directory/calendar/list: once daily | C8: global | D8: =Assumptions!$B$16*Assumptions!$B$6 -> 30
A9: lookup_demand | B9: Demand-only lookup, 50% cache misses | C9: demand | D9: =0 -> 0
A10: entity_crypto | B10: Optional crypto: every 5 min, 24 h/day | C10: entity | D10: =Assumptions!$B$18*60/Assumptions!$B$10*Assumptions!$B$6 -> 8640
A11: entity_onchain | B11: Tokenized/perpetual venues: hourly, 24 h/day | C11: entity | D11: =24*60/Assumptions!$B$19*Assumptions!$B$6 -> 720
A12: global_premarket | B12: Shared premarket list: every 5 min, 5.5 h, 22 days | C12: global | D12: =Assumptions!$B$20*60/Assumptions!$B$10*Assumptions!$B$5 -> 1452

Sheet Company tools
A1: ID | B1: Provider | C1: Endpoint | D1: What it provides | E1: Company coverage | F1: Accuracy assessment | G1: Freshness / real time | H1: Response speed | I1: MVP relevance | J1: Possible platform feature | K1: Specific limitations | L1: Official source status | M1: Permissions | N1: Operational safety | O1: Confirmed users | P1: Intended users (assessment) | Q1: Exact catalogue source
A2: T01 | B2: nasdaq | C2: /get_stock_earnings | D2: Reported earnings and expectations | E2: Unknown Monid count; US exchange-listed source scope, tool dependent. | F2: Good source-checking potential; reconcile selected values to company filings. | G2: Reporting-cycle data, often quarterly/annual; monitor revisions. | H2: Unmeasured: no paid endpoint latency benchmark or confirmed Monid SLA. | I2: High | J2: Company earnings card and results alerts | K2: Actuals and analyst estimates must remain separate; expected dates can change. | L2: See P1 source/provenance assessment; Monid authority unverified. | M2: See P1 rights assessment; customer display/storage grant unverified. | N2: Not security-audited. Server-side credentials, endpoint allowlist, input validation and spending caps proposed; no verified Monid SLA or contractual security assurance. | O2: No named customer verified for this exact Monid connector. | P2: Fundamental analysts and company researchers | Q2: Metadata: T01
A3: T02 | B3: nasdaq | C3: /get_stock_screener | D3: Filter listed stocks | E3: Unknown Monid count; US exchange-listed source scope, tool dependent. | F3: Useful discovery subset; ranking/filter completeness unmeasured. | G3: Depends on underlying fields and refresh schedule; not a full market tape. | H3: Unmeasured: no paid endpoint latency benchmark or confirmed Monid SLA. | I3: Medium | J3: Catalogue discovery and saved screens | K3: Universe, pagination and filter parity with Nasdaq are unverified. | L3: See P1 source/provenance assessment; Monid authority unverified. | M3: See P1 rights assessment; customer display/storage grant unverified. | N3: Not security-audited. Server-side credentials, endpoint allowlist, input validation and spending caps proposed; no verified Monid SLA or contractual security assurance. | O3: No named customer verified for this exact Monid connector. | P3: Investors and company/market researchers | Q3: Metadata: T02
A4: T03 | B4: nasdaq | C4: /get_earnings_calendar | D4: Upcoming earnings dates | E4: Unknown Monid count; US exchange-listed source scope, tool dependent. | F4: Useful for planning; flag estimated, confirmed, postponed and cancelled states. | G4: Event-driven revisions; expected dates can change. | H4: Unmeasured: no paid endpoint latency benchmark or confirmed Monid SLA. | I4: Medium | J4: Shared earnings calendar matched to holdings | K4: Some dates are algorithmic estimates; mark confirmed versus estimated. | L4: See P1 source/provenance assessment; Monid authority unverified. | M4: See P1 rights assessment; customer display/storage grant unverified. | N4: Not security-audited. Server-side credentials, endpoint allowlist, input validation and spending caps proposed; no verified Monid SLA or contractual security assurance. | O4: No named customer verified for this exact Monid connector. | P4: Investors and company/market researchers | Q4: Metadata: T03
A5: T04 | B5: nasdaq | C5: /get_stock_sec_filings | D5: Company filing records and source links | E5: Unknown Monid count; US exchange-listed source scope, tool dependent. | F5: High auditability only when accession/source links survive. | G5: After filing publication, not when the underlying event happened. | H5: Unmeasured: no paid endpoint latency benchmark or confirmed Monid SLA. | I5: High | J5: Company filing timeline and original-document links | K5: General filing discovery; confirm accession IDs, form filters and amendments. | L5: See P1 source/provenance assessment; Monid authority unverified. | M5: See P1 rights assessment; customer display/storage grant unverified. | N5: Not security-audited. Server-side credentials, endpoint allowlist, input validation and spending caps proposed; no verified Monid SLA or contractual security assurance. | O5: No named customer verified for this exact Monid connector. | P5: Investors and company/market researchers | Q5: Metadata: T04
A6: T05 | B6: nasdaq | C6: /get_mutual_fund_quote | D6: Mutual-fund price or NAV snapshot | E6: Unknown Monid count; US exchange-listed source scope, tool dependent. | F6: Check official fund NAV and valuation date. | G6: Periodic NAV; not an intraday equity feed. | H6: Unmeasured: no paid endpoint latency benchmark or confirmed Monid SLA. | I6: Medium; optional feature | J6: Optional fund facts panel | K6: Fund NAV is typically periodic; this is not a live stock quote or company count. | L6: See P1 source/provenance assessment; Monid authority unverified. | M6: See P1 rights assessment; customer display/storage grant unverified. | N6: Not security-audited. Server-side credentials, endpoint allowlist, input validation and spending caps proposed; no verified Monid SLA or contractual security assurance. | O6: No named customer verified for this exact Monid connector. | P6: Investors and company/market researchers | Q6: Metadata: T05
A7: T06 | B7: nasdaq | C7: /get_stock_dividend_history | D7: Past dividend payments | E7: Unknown Monid count; US exchange-listed source scope, tool dependent. | F7: Good source-checking potential; reconcile selected values to company filings. | G7: Reporting-cycle data, often quarterly/annual; monitor revisions. | H7: Unmeasured: no paid endpoint latency benchmark or confirmed Monid SLA. | I7: High | J7: Company income and distribution history | K7: Past dividends do not guarantee future payments; distinguish ex-date and payment date. | L7: See P1 source/provenance assessment; Monid authority unverified. | M7: See P1 rights assessment; customer display/storage grant unverified. | N7: Not security-audited. Server-side credentials, endpoint allowlist, input validation and spending caps proposed; no verified Monid SLA or contractual security assurance. | O7: No named customer verified for this exact Monid connector. | P7: Fundamental analysts and company researchers | Q7: Metadata: T06
A8: T07 | B8: nasdaq | C8: /get_stock_quote | D8: Stock quote snapshot | E8: Unknown Monid count; US exchange-listed source scope, tool dependent. | F8: Useful for a timestamped price display; correctness unmeasured through Monid. | G8: Potentially frequent upstream updates; no verified Monid real-time delivery. | H8: Unmeasured: no paid endpoint latency benchmark or confirmed Monid SLA. | I8: High | J8: Company header and watchlist price card | K8: Website quote updates do not establish Monid feed latency or exchange entitlement. | L8: See P1 source/provenance assessment; Monid authority unverified. | M8: See P1 rights assessment; customer display/storage grant unverified. | N8: Not security-audited. Server-side credentials, endpoint allowlist, input validation and spending caps proposed; no verified Monid SLA or contractual security assurance. | O8: No named customer verified for this exact Monid connector. | P8: Investors and company/market researchers | Q8: Metadata: T07
A9: T08 | B9: nasdaq | C9: /search_symbols | D9: Search security identifiers | E9: Unknown Monid count; US exchange-listed source scope, tool dependent. | F9: Useful candidate matching; validate exchange, instrument type and issuer identifiers. | G9: Mostly reference data; newly listed, delisted and renamed securities need updates. | H9: Unmeasured: no paid endpoint latency benchmark or confirmed Monid SLA. | I9: Medium | J9: Catalogue symbol resolver | K9: Interactive search is not a complete security master; exchange collisions need resolution. | L9: See P1 source/provenance assessment; Monid authority unverified. | M9: See P1 rights assessment; customer display/storage grant unverified. | N9: Not security-audited. Server-side credentials, endpoint allowlist, input validation and spending caps proposed; no verified Monid SLA or contractual security assurance. | O9: No named customer verified for this exact Monid connector. | P9: Catalogue users and data operations | Q9: Metadata: T08
A10: T09 | B10: nasdaq | C10: /get_market_indices | D10: Broad market index overview | E10: Unknown Monid count; US exchange-listed source scope, tool dependent. | F10: Useful for a timestamped price display; correctness unmeasured through Monid. | G10: Potentially frequent upstream updates; no verified Monid real-time delivery. | H10: Unmeasured: no paid endpoint latency benchmark or confirmed Monid SLA. | I10: High | J10: Global markets overview | K10: Index levels are not company coverage; provider-specific index delays apply. | L10: See P1 source/provenance assessment; Monid authority unverified. | M10: See P1 rights assessment; customer display/storage grant unverified. | N10: Not security-audited. Server-side credentials, endpoint allowlist, input validation and spending caps proposed; no verified Monid SLA or contractual security assurance. | O10: No named customer verified for this exact Monid connector. | P10: Investors and company/market researchers | Q10: Metadata: T09
A11: T10 | B11: nasdaq | C11: /get_stock_historical_quotes | D11: Historical stock price observations | E11: Unknown Monid count; US exchange-listed source scope, tool dependent. | F11: Validate adjustments, gaps, timestamps and price units against an authorised reference. | G11: Historical bars; interval size does not prove delivery latency. | H11: Unmeasured: no paid endpoint latency benchmark or confirmed Monid SLA. | I11: High | J11: Company historical price chart | K11: Confirm adjusted prices, corporate actions and maximum history. The same-named Parse wrapper describes end-of-day history only; its relationship to Monid is unverified. | L11: See P1 source/provenance assessment; Monid authority unverified. | M11: See P1 rights assessment; customer display/storage grant unverified. | N11: Not security-audited. Server-side credentials, endpoint allowlist, input validation and spending caps proposed; no verified Monid SLA or contractual security assurance. | O11: No named customer verified for this exact Monid connector. | P11: Investors and company/market researchers | Q11: Metadata: T10
A12: T12 | B12: nasdaq | C12: /get_market_movers | D12: Leading price movers | E12: Unknown Monid count; US exchange-listed source scope, tool dependent. | F12: Useful discovery subset; ranking/filter completeness unmeasured. | G12: Depends on underlying fields and refresh schedule; not a full market tape. | H12: Unmeasured: no paid endpoint latency benchmark or confirmed Monid SLA. | I12: Medium | J12: Market discovery panel | K12: Ranking is a selected subset, not all stocks; volume and reference session matter. | L12: See P1 source/provenance assessment; Monid authority unverified. | M12: See P1 rights assessment; customer display/storage grant unverified. | N12: Not security-audited. Server-side credentials, endpoint allowlist, input validation and spending caps proposed; no verified Monid SLA or contractual security assurance. | O12: No named customer verified for this exact Monid connector. | P12: Investors and company/market researchers | Q12: Metadata: T12
... A56: T59 | B56: defillama | C56: /equities/v1/dimensions | D56: Quarterly/annual revenue, holder-revenue, earnings and share series | E56: Unknown exact count; supported ticker/country directory exists. | F56: Validate methodology, source fields and period consistency. | G56: Dependent on underlying source updates and calculation window. | H56: Unmeasured: no paid endpoint latency benchmark or confirmed Monid SLA. | I56: Medium | J56: Company financial-trend comparisons | K56: Defined financial metric series, not arbitrary operational KPIs or business/geographic segments; validate periods and company completeness. | L56: See P6 source/provenance assessment; Monid authority unverified. | M56: See P6 rights assessment; customer display/storage grant unverified. | N56: Not security-audited. Server-side credentials, endpoint allowlist, input validation and spending caps proposed; no verified Monid SLA or contractual security assurance. | O56: No named customer verified for this exact Monid connector. | P56: Investors and company/market researchers | Q56: Metadata: T59

Sheet Insider tools
A1: ID | B1: Provider | C1: Endpoint | D1: What it provides | E1: Company coverage | F1: Accuracy assessment | G1: Freshness / real time | H1: Response speed | I1: MVP relevance | J1: Possible platform feature | K1: Specific limitations | L1: Official source status | M1: Permissions | N1: Operational safety | O1: Confirmed users | P1: Intended users (assessment) | Q1: Exact catalogue source
A2: T11 | B2: nasdaq | C2: /get_stock_institutional_holdings | D2: Institutional ownership records | E2: Unknown Monid count; US exchange-listed source scope, tool dependent. | F2: Reconcile reporting manager, quarter, security class and amendments. | G2: Periodic, historically reported holdings; not real-time ownership. | H2: Unmeasured: no paid endpoint latency benchmark or confirmed Monid SLA. | I2: Medium | J2: Company ownership and investor changes | K2: Institutional filings describe historical positions; not same-day insider trades. | L2: See P1 source/provenance assessment; Monid authority unverified. | M2: See P1 rights assessment; customer display/storage grant unverified. | N2: Not security-audited. Server-side credentials, endpoint allowlist, input validation and spending caps proposed; no verified Monid SLA or contractual security assurance. | O2: No named customer verified for this exact Monid connector. | P2: Company and institutional-portfolio researchers | Q2: Metadata: T11
A3: T27 | B3: finviz | C3: /get_insider_trading | D3: Recent reported insider transactions | E3: Website: 5,613 stock ticker rows observed; exact Monid/per-tool count unknown. | F3: High auditability with original filing; parsing and transaction interpretation need checks. | G3: Disclosure-lagged; vendor ingestion lag and Monid tier unmeasured. | H3: Unmeasured: no paid endpoint latency benchmark or confirmed Monid SLA. | I3: High | J3: Shared insider activity feed filtered to holdings | K3: Verify original forms, transaction codes, dates and amendments. A same-named Parse sample labels a Form 144 proposed-sale link as Form 4; this is not a tested Monid defect or proof of a completed sale. | L3: See P3 source/provenance assessment; Monid authority unverified. | M3: See P3 rights assessment; customer display/storage grant unverified. | N3: Not security-audited. Server-side credentials, endpoint allowlist, input validation and spending caps proposed; no verified Monid SLA or contractual security assurance. | O3: No named customer verified for this exact Monid connector. | P3: Investors studying executive disclosures | Q3: Metadata: T27
A4: T32 | B4: marketbeat | C4: /get_institutional_ownership | D4: Institutional holders and ownership changes | E4: Website claim: 20,000 company profiles; Monid/per-tool count unknown. | F4: Reconcile reporting manager, quarter, security class and amendments. | G4: Periodic, historically reported holdings; not real-time ownership. | H4: Unmeasured: no paid endpoint latency benchmark or confirmed Monid SLA. | I4: Medium | J4: Ownership tab with filing dates | K4: Historical institution positions are not director/officer transactions or current portfolios. | L4: See P4 source/provenance assessment; Monid authority unverified. | M4: See P4 rights assessment; customer display/storage grant unverified. | N4: Not security-audited. Server-side credentials, endpoint allowlist, input validation and spending caps proposed; no verified Monid SLA or contractual security assurance. | O4: No named customer verified for this exact Monid connector. | P4: Company and institutional-portfolio researchers | Q4: Metadata: T32
A5: T34 | B5: marketbeat | C5: /get_insider_trades | D5: Company insider transactions | E5: Website claim: 20,000 company profiles; Monid/per-tool count unknown. | F5: High auditability with original filing; parsing and transaction interpretation need checks. | G5: Disclosure-lagged; vendor ingestion lag and Monid tier unmeasured. | H5: Unmeasured: no paid endpoint latency benchmark or confirmed Monid SLA. | I5: High | J5: Company insider timeline and holding alerts | K5: Reported transactions need original SEC links, codes and amendment handling. | L5: See P4 source/provenance assessment; Monid authority unverified. | M5: See P4 rights assessment; customer display/storage grant unverified. | N5: Not security-audited. Server-side credentials, endpoint allowlist, input validation and spending caps proposed; no verified Monid SLA or contractual security assurance. | O5: No named customer verified for this exact Monid connector. | P5: Investors studying executive disclosures | Q5: Metadata: T34
A6: T60 | B6: secform4 | C6: /search | D6: Search insider and ownership filings | E6: Unknown company/CIK count; SEC-derived issuer/owner universe. | F6: Useful candidate matching; validate exchange, instrument type and issuer identifiers. | G6: Mostly reference data; newly listed, delisted and renamed securities need updates. | H6: Unmeasured: no paid endpoint latency benchmark or confirmed Monid SLA. | I6: Medium | J6: Insider research search | K6: Search scope and pagination unverified; company and owner identifiers are different. | L6: See P7 source/provenance assessment; Monid authority unverified. | M6: See P7 rights assessment; customer display/storage grant unverified. | N6: Not security-audited. Server-side credentials, endpoint allowlist, input validation and spending caps proposed; no verified Monid SLA or contractual security assurance. | O6: No named customer verified for this exact Monid connector. | P6: Catalogue users and data operations | Q6: Metadata: T60
A7: T61 | B7: secform4 | C7: /get_13d_filings | D7: Activist or significant beneficial-ownership disclosures | E7: Unknown company/CIK count; SEC-derived issuer/owner universe. | F7: Verify original schedule, ownership basis, filer type and amendments. | G7: Disclosure-triggered; not a real-time transaction stream. | H7: Unmeasured: no paid endpoint latency benchmark or confirmed Monid SLA. | I7: High | J7: Ownership-event alerts linked to original filings | K7: 13D is beneficial ownership, not a complete trade tape; filing deadlines differ from Form 4. | L7: See P7 source/provenance assessment; Monid authority unverified. | M7: See P7 rights assessment; customer display/storage grant unverified. | N7: Not security-audited. Server-side credentials, endpoint allowlist, input validation and spending caps proposed; no verified Monid SLA or contractual security assurance. | O7: No named customer verified for this exact Monid connector. | P7: Ownership and event researchers | Q7: Metadata: T61
A8: T62 | B8: secform4 | C8: /get_insider_sales | D8: Reported insider sale list | E8: Unknown company/CIK count; SEC-derived issuer/owner universe. | F8: High auditability with original filing; parsing and transaction interpretation need checks. | G8: Disclosure-lagged; vendor ingestion lag and Monid tier unmeasured. | H8: Unmeasured: no paid endpoint latency benchmark or confirmed Monid SLA. | I8: High | J8: Shared insider-sales feed | K8: Public source module explicitly six months delayed; Monid entitlement and actual freshness unknown. | L8: See P7 source/provenance assessment; Monid authority unverified. | M8: See P7 rights assessment; customer display/storage grant unverified. | N8: Not security-audited. Server-side credentials, endpoint allowlist, input validation and spending caps proposed; no verified Monid SLA or contractual security assurance. | O8: No named customer verified for this exact Monid connector. | P8: Investors studying executive disclosures | Q8: Metadata: T62
A9: T63 | B9: secform4 | C9: /get_significant_insider_buys | D9: Selected large insider purchases | E9: Unknown company/CIK count; SEC-derived issuer/owner universe. | F9: High auditability with original filing; parsing and transaction interpretation need checks. | G9: Disclosure-lagged; vendor ingestion lag and Monid tier unmeasured. | H9: Unmeasured: no paid endpoint latency benchmark or confirmed Monid SLA. | I9: High | J9: Prioritised insider alert queue | K9: Public source six-month delay; vendor selection threshold is not evidence of investment quality. | L9: See P7 source/provenance assessment; Monid authority unverified. | M9: See P7 rights assessment; customer display/storage grant unverified. | N9: Not security-audited. Server-side credentials, endpoint allowlist, input validation and spending caps proposed; no verified Monid SLA or contractual security assurance. | O9: No named customer verified for this exact Monid connector. | P9: Investors studying executive disclosures | Q9: Metadata: T63
A10: T64 | B10: secform4 | C10: /get_institution_holders | D10: Institutional holders of an issuer | E10: Unknown company/CIK count; SEC-derived issuer/owner universe. | F10: Reconcile reporting manager, quarter, security class and amendments. | G10: Periodic, historically reported holdings; not real-time ownership. | H10: Unmeasured: no paid endpoint latency benchmark or confirmed Monid SLA. | I10: Medium | J10: Company ownership history | K10: Reported holdings lag quarter-end; holder population and security class matching matter. | L10: See P7 source/provenance assessment; Monid authority unverified. | M10: See P7 rights assessment; customer display/storage grant unverified. | N10: Not security-audited. Server-side credentials, endpoint allowlist, input validation and spending caps proposed; no verified Monid SLA or contractual security assurance. | O10: No named customer verified for this exact Monid connector. | P10: Company and institutional-portfolio researchers | Q10: Metadata: T64
A11: T65 | B11: secform4 | C11: /get_insider_buy_sell_ratios | D11: Aggregated insider purchase/sale ratios | E11: Unknown company/CIK count; SEC-derived issuer/owner universe. | F11: Validate methodology, source fields and period consistency. | G11: Dependent on underlying source updates and calculation window. | H11: Unmeasured: no paid endpoint latency benchmark or confirmed Monid SLA. | I11: Medium | J11: Labelled insider-activity indicator | K11: Public source six-month delay; ratios depend on transaction types, window and reporting population. | L11: See P7 source/provenance assessment; Monid authority unverified. | M11: See P7 rights assessment; customer display/storage grant unverified. | N11: Not security-audited. Server-side credentials, endpoint allowlist, input validation and spending caps proposed; no verified Monid SLA or contractual security assurance. | O11: No named customer verified for this exact Monid connector. | P11: Investors and company/market researchers | Q11: Metadata: T65
A12: T66 | B12: secform4 | C12: /get_stock_options | D12: Insider option-related transactions | E12: Unknown company/CIK count; SEC-derived issuer/owner universe. | F12: High auditability with original filing; parsing and transaction interpretation need checks. | G12: Disclosure-lagged; vendor ingestion lag and Monid tier unmeasured. | H12: Unmeasured: no paid endpoint latency benchmark or confirmed Monid SLA. | I12: High | J12: Compensation versus cash-purchase explanation | K12: Insider option disclosures, not an exchange option chain; public module six months delayed. | L12: See P7 source/provenance assessment; Monid authority unverified. | M12: See P7 rights assessment; customer display/storage grant unverified. | N12: Not security-audited. Server-side credentials, endpoint allowlist, input validation and spending caps proposed; no verified Monid SLA or contractual security assurance. | O12: No named customer verified for this exact Monid connector. | P12: Investors studying executive disclosures | Q12: Metadata: T66
... A16: T70 | B16: secform4 | C16: /get_13g_filings | D16: Passive or qualified beneficial-ownership disclosures | E16: Unknown company/CIK count; SEC-derived issuer/owner universe. | F16: Verify original schedule, ownership basis, filer type and amendments. | G16: Disclosure-triggered; not a real-time transaction stream. | H16: Unmeasured: no paid endpoint latency benchmark or confirmed Monid SLA. | I16: High | J16: Company ownership notifications | K16: 13G filing cadence depends on filer type and triggering change; not immediate trading activity. | L16: See P7 source/provenance assessment; Monid authority unverified. | M16: See P7 rights assessment; customer display/storage grant unverified. | N16: Not security-audited. Server-side credentials, endpoint allowlist, input validation and spending caps proposed; no verified Monid SLA or contractual security assurance. | O16: No named customer verified for this exact Monid connector. | P16: Ownership and event researchers | Q16: Metadata: T70

Sheet Provider evidence
A1: Code | B1: Provider | C1: Tools | D1: Coverage | E1: Official provenance | F1: Accuracy / quality | G1: Upstream freshness | H1: Permissions / suitability | I1: Audience and adoption distinction | J1: Recommendation | K1: Source URLs
A2: P1 | B2: Nasdaq | C2: 20 | D2: No exact Monid company count verified. Related official feeds cover US exchange-listed securities; each news, fund, options and filing tool can cover a different subset. | E2: Nasdaq is an official exchange operator. Its website also republishes third-party company data and journalism. These Monid listings are not verified as licensed Nasdaq feeds. | F2: Strong potential traceability for exchange data and original filings; mixed confidence for estimates, third-party news and derived fields. No measured connector accuracy. | G2: Website quote bar: three-second refresh; indices at least one minute delayed. Short interest is twice-monthly. Neither establishes Monid delivery latency. The separate official Retail Trading Activity Tracker is daily with a one-day reporting lag. | H2: Nasdaq website terms restrict automated capture and commercial copying, storage and derivative products without consent. A separate licensed feed/distributor agreement is the relevant route; no Monid pass-through grant established. | I2: Retail investors and analysts are the apparent audience. Trading 212 and Microsoft Excel are named users of the separate direct Nasdaq Last Sale product, not these Monid tools. | J2: Conditional research candidate; use an authorised Nasdaq route for critical prices. | K2: https://www.nasdaq.com/products/data/equities/nasdaq-last-sale https://www.nasdaq.com/market-activity/stocks/aapl https://www.nasdaq.com/market-activity https://www.nasdaq.com/market-activity/stocks/aapl/financials https://nasdaqtrader.com/trader.aspx?id=ShortInterest https://data.nasdaq.com/databases/RTAT/documentation?anchor=sample-data https://www.nasdaq.com/legal https://www.nasdaq.com/market-activity/stocks/aapl/institutional-holdings
A3: P2 | B3: Yahoo Finance | C3: 5 | D3: Global exchanges are listed in Yahoo help, but no exact company or news count was verified for Monid. Quote, profile and headline coverage are different questions. | E3: Publisher and secondary financial-data aggregator. Not the original issuer of every article or price record; Monid distribution authority unverified. | F3: Useful international research scope, but adjustments, stale profiles, article duplicates and ticker matching need measurement. No accuracy percentage established. | G3: Exchange dependent: the official table includes real-time Nasdaq, 15-minute OPRA/OTC, 20-minute ASX and 30-minute Shanghai/Shenzhen. Monid adds unmeasured collection/cache lag. | H3: Yahoo Finance help prohibits redistribution of its displayed/provided information. No separate Monid grant was verified. Article and photo rights require their own entitlement. | I3: Suitable for individual investors and analysts (product assessment); no named production customer verified for these Monid endpoints. | J3: On-demand alternative only after rights resolution; comparatively costly for frequent polling. | K3: https://help.yahoo.com/kb/finance/SLN2310.html https://legal.yahoo.com/us/en/yahoo/terms/product-atos/finance/index.html
A4: P3 | B4: Finviz | C4: 5 | D4: The stock-only website screener showed 5,613 ticker rows; the unrestricted version 11,614 including funds. These dynamic observations are not unique companies, insider/news coverage or Monid-supported totals. Source FAQ lists Nasdaq, NYSE and AMEX. | E4: Secondary screener/aggregator. Direct Elite API/export access exists, but the Monid connector is not verified as that authorised product. | F4: Useful screening context, subject to universe/result caps. Sentiment is an interpretation, with no validated model or factual-accuracy score established. | G4: Free website stock quotes are one minute delayed; Elite quotes can be real time; fundamentals refresh hourly. News/insider latency and Monid refresh remain unknown. | H4: Direct API policy is personal-use and prohibits third-party redistribution/resale. Its one-request-per-five-seconds limit is not a verified Monid limit. A personal Elite subscription is not a licence for our app users. | I4: Finviz addresses beginners and professional traders. No named production customer verified for these Monid tools. | J4: Potential screener feature, secondary priority; resolve licence and pagination first. | K4: https://finviz.com/help/faq https://finviz.com/screener?f=ind_stocksonly&v=111 https://finviz.com/screener?v=111 https://finviz.com/knowledge-base/market-data-research/api/usage-limits https://finviz.com/elite
A5: P4 | B5: MarketBeat | C5: 14 | D5: Website advertises 20,000 public-company profiles, with US, Canadian and UK sections. No exact Monid count or assurance that all 14 tools cover all these companies was verified. | E5: Private publisher and aggregator; discloses market-data suppliers and editorial policies. SEC-derived insider tables remain secondary. | F5: Editorial source checks and corrections are positive signals, not a measured endpoint error rate. Some summaries use AI; ratings/forecasts and MarketRank are opinions or models. | G5: Source fair-market-value estimates update each minute; other Barchart market data is at least ten minutes delayed. Model scores, earnings and holdings have different cadences; Monid latency unmeasured. | H5: Terms distinguish personal access, site/XML licences and commercial licensing, and restrict bulk redistribution. No Monid downstream customer-display/storage grant established. | I5: Retail-investor publisher with a large claimed newsletter readership. This is audience evidence, not named Monid API-customer evidence. | J5: One of the more relevant headline/research candidates, conditional on a valid commercial licence. | K5: https://www.marketbeat.com/about/ https://www.marketbeat.com/editorial-guidelines/ https://www.marketbeat.com/faq/ https://www.marketbeat.com/terms/ https://www.marketbeat.com/all-access/insider-trades-screener/
A6: P5 | B6: StockAnalysis | C6: 7 | D6: Website advertises 130,000+ tradable symbols worldwide, including ETFs and multiple listings. This is not a unique-company number or proven Monid coverage. Seven listings were retrievable although eight were advertised. | E6: Secondary research publisher using providers including S&P Global and Fiscal.ai. It explicitly says it has no programmatic API/MCP and lacks programmatic resale rights. | F6: Documented upstream vendors and review practices support manual research. No independent Monid accuracy or completeness benchmark; derived ratios and financial periods need reconciliation. | G6: US website stock pages refresh every five seconds for free users and stream for paid users; source screeners are roughly minute-based; other markets can be delayed or end-of-day. This is not Monid streaming evidence. | H6: Published no-programmatic-access position is a concrete blocker for assuming these are official licensed APIs. A valid, separately evidenced upstream rights chain would be needed before production use. | I6: Regular/individual investors are its stated audience. No named Monid endpoint customers verified. | J6: Hold production integration pending an explanation and proof of lawful programmatic supply. | K6: https://stockanalysis.com/help/data-and-downloads/about-our-data/ https://stockanalysis.com/data-sources/ https://stockanalysis.com/help/faq/stock-price-data/ https://stockanalysis.com/help/faq/api-access/ https://stockanalysis.com/terms-of-use/ https://stockanalysis.com/about/
A7: P6 | B7: DefiLlama equities | C7: 8 | D7: Exact supported company count unverified. Official companies-list returns ticker/country identities to enumerate and match; upstream Twelve Data breadth is not proof of this beta subset. | E7: All eight paths are documented in the vendor’s official Pro API. Equities market/fundamental data is secondary Twelve Data; filing links can lead to primary SEC documents. Monid resale authority remains unverified. | F7: Clearer documented schemas than the web-style wrappers, but beta stability, per-field coverage and source reconciliation need validation. | G7: Beta snapshot/chart service, not a demonstrated tick stream. Short-window charts may use five-minute bars with daily fallback; on-chain venue mappings are hourly. End-to-end lag unmeasured. | H7: DefiLlama API terms and underlying Twelve Data display/redistribution entitlements apply. No confirmed pass-through customer-display grant through Monid. Direct Pro API pricing is a separate purchase route. | I7: Potential audience: equity and crypto researchers. No named adopter of these exact beta equities/Monid endpoints verified. | J7: Best low-cost documented API candidate for a limited fundamentals/chart evaluation, after rights and coverage checks. | K7: https://api-docs.defillama.com/ https://github.com/DefiLlama/api-docs/blob/main/llms-pro.txt https://defillama.com/equities https://defillama.com/terms/ https://twelvedata.com/terms
A8: P7 | B8: SECForm4.com | C8: 11 | D8: No exact company, issuer-CIK or manager count verified for Monid. SEC filing coverage is not a worldwide 50,000-company universe; owner, security and transaction counts are different. | E8: Private SEC-data aggregator, not the SEC. Original accession numbers/documents are needed to establish each record’s provenance. | F8: Potentially highly auditable with originals, but no tested error rate. Amendments, joint reporting, rounded totals and non-split-adjusted shares need handling. | G8: Five public modules disclose a six-month delay: buys, sales, significant buys, insider options and ratios. Company history can be newer. Monid subscription tier and delivered freshness are unverified. | H8: Website subscriptions do not establish a redistribution/API licence. No public grant for Monid customer display, history storage or exports was established. | I8: Investors studying executives and institutions are the intended audience. No named production customer verified for these Monid endpoints. | J8: Do not promise timely insider alerts until tier/lag/rights are proven; prefer official SEC ingestion as the foundation. | K8: https://www.secform4.com/ https://www.secform4.com/all-buys https://www.secform4.com/insider-sales https://www.secform4.com/significant-buys https://www.secform4.com/stock-options https://www.secform4.com/insider-buy-sell-ratios https://www.secform4.com/insider-trading/320193.htm https://www.secform4.com/account/sign-up https://monid.ai/blog/guides/insider-trading-api-form-4-data

Sheet Costs
A1: ID | B1: Provider | C1: Endpoint | D1: Scope | E1: Profile | F1: USD / call | G1: Include? 0/1 | H1: Keys override: 10 | I1: Keys override: 100 | J1: Entities / call | K1: Pages / poll or lookup | L1: Retry overhead | M1: Polls / key / month | N1: Effective keys: 10 | O1: Effective keys: 100 | P1: Research calls: 10 | Q1: Research calls: 100 | R1: Research USD: 10 | S1: Research USD: 100 | T1: Feed calls: 10 | U1: Feed calls: 100 | V1: Feed USD: 10 | W1: Feed USD: 100 | X1: Scope / caveat | Y1: Metadata
A2: T01 | B2: nasdaq | C2: /get_stock_earnings | D2: entity | E2: entity_daily | F2: 0.01 | G2: 0 | H2: 0 | I2: 0 | J2: 1 | K2: 1 | L2: 0 | M2: =Profiles!D7 -> 30 | N2: =IF(H2>0,H2,IF(D2="entity",MAX(Assumptions!$B$7,ROUNDUP(Assumptions!$B$2*Assumptions!$B$7*Assumptions!$B$8,0)),1)) -> 100 | O2: =IF(I2>0,I2,IF(D2="entity",MAX(Assumptions!$B$7,ROUNDUP(Assumptions!$B$3*Assumptions!$B$7*Assumptions!$B$8,0)),1)) -> 1000 | P2: =ROUNDUP(Assumptions!$B$2*Assumptions!$B$4*Assumptions!$B$5/J2,0)*K2*(1+L2) -> 1100 | Q2: =ROUNDUP(Assumptions!$B$3*Assumptions!$B$4*Assumptions!$B$5/J2,0)*K2*(1+L2) -> 11000 | R2: =P2*F2 -> 11 | S2: =Q2*F2 -> 110 | T2: =IF(D2="demand",P2*Assumptions!$B$17,ROUNDUP(N2/J2,0)*M2*K2*(1+L2)) -> 3000 | U2: =IF(D2="demand",Q2*Assumptions!$B$17,ROUNDUP(O2/J2,0)*M2*K2*(1+L2)) -> 30000 | V2: =T2*F2 -> 30 | W2: =U2*F2 -> 300 | X2: One page/query assumed; full coverage and pagination unverified. Shared union of followed keys for entity tools; one shared list for global tools. | Y2: Catalogue price/source
A3: T02 | B3: nasdaq | C3: /get_stock_screener | D3: global | E3: global_market | F3: 0.01 | G3: 0 | H3: 0 | I3: 0 | J3: 1 | K3: 1 | L3: 0 | M3: =Profiles!D3 -> 1716 | N3: =IF(H3>0,H3,IF(D3="entity",MAX(Assumptions!$B$7,ROUNDUP(Assumptions!$B$2*Assumptions!$B$7*Assumptions!$B$8,0)),1)) -> 1 | O3: =IF(I3>0,I3,IF(D3="entity",MAX(Assumptions!$B$7,ROUNDUP(Assumptions!$B$3*Assumptions!$B$7*Assumptions!$B$8,0)),1)) -> 1 | P3: =ROUNDUP(Assumptions!$B$2*Assumptions!$B$4*Assumptions!$B$5/J3,0)*K3*(1+L3) -> 1100 | Q3: =ROUNDUP(Assumptions!$B$3*Assumptions!$B$4*Assumptions!$B$5/J3,0)*K3*(1+L3) -> 11000 | R3: =P3*F3 -> 11 | S3: =Q3*F3 -> 110 | T3: =IF(D3="demand",P3*Assumptions!$B$17,ROUNDUP(N3/J3,0)*M3*K3*(1+L3)) -> 1716 | U3: =IF(D3="demand",Q3*Assumptions!$B$17,ROUNDUP(O3/J3,0)*M3*K3*(1+L3)) -> 1716 | V3: =T3*F3 -> 17.16 | W3: =U3*F3 -> 17.16 | X3: One page/query assumed; full coverage and pagination unverified. Shared union of followed keys for entity tools; one shared list for global tools. | Y3: Catalogue price/source
A4: T03 | B4: nasdaq | C4: /get_earnings_calendar | D4: global | E4: global_daily | F4: 0.01 | G4: 0 | H4: 0 | I4: 0 | J4: 1 | K4: 1 | L4: 0 | M4: =Profiles!D8 -> 30 | N4: =IF(H4>0,H4,IF(D4="entity",MAX(Assumptions!$B$7,ROUNDUP(Assumptions!$B$2*Assumptions!$B$7*Assumptions!$B$8,0)),1)) -> 1 | O4: =IF(I4>0,I4,IF(D4="entity",MAX(Assumptions!$B$7,ROUNDUP(Assumptions!$B$3*Assumptions!$B$7*Assumptions!$B$8,0)),1)) -> 1 | P4: =ROUNDUP(Assumptions!$B$2*Assumptions!$B$4*Assumptions!$B$5/J4,0)*K4*(1+L4) -> 1100 | Q4: =ROUNDUP(Assumptions!$B$3*Assumptions!$B$4*Assumptions!$B$5/J4,0)*K4*(1+L4) -> 11000 | R4: =P4*F4 -> 11 | S4: =Q4*F4 -> 110 | T4: =IF(D4="demand",P4*Assumptions!$B$17,ROUNDUP(N4/J4,0)*M4*K4*(1+L4)) -> 30 | U4: =IF(D4="demand",Q4*Assumptions!$B$17,ROUNDUP(O4/J4,0)*M4*K4*(1+L4)) -> 30 | V4: =T4*F4 -> 0.3 | W4: =U4*F4 -> 0.3 | X4: One page/query assumed; full coverage and pagination unverified. Shared union of followed keys for entity tools; one shared list for global tools. | Y4: Catalogue price/source
A5: T04 | B5: nasdaq | C5: /get_stock_sec_filings | D5: entity | E5: entity_hourly | F5: 0.01 | G5: 0 | H5: 0 | I5: 0 | J5: 1 | K5: 1 | L5: 0 | M5: =Profiles!D5 -> 352 | N5: =IF(H5>0,H5,IF(D5="entity",MAX(Assumptions!$B$7,ROUNDUP(Assumptions!$B$2*Assumptions!$B$7*Assumptions!$B$8,0)),1)) -> 100 | O5: =IF(I5>0,I5,IF(D5="entity",MAX(Assumptions!$B$7,ROUNDUP(Assumptions!$B$3*Assumptions!$B$7*Assumptions!$B$8,0)),1)) -> 1000 | P5: =ROUNDUP(Assumptions!$B$2*Assumptions!$B$4*Assumptions!$B$5/J5,0)*K5*(1+L5) -> 1100 | Q5: =ROUNDUP(Assumptions!$B$3*Assumptions!$B$4*Assumptions!$B$5/J5,0)*K5*(1+L5) -> 11000 | R5: =P5*F5 -> 11 | S5: =Q5*F5 -> 110 | T5: =IF(D5="demand",P5*Assumptions!$B$17,ROUNDUP(N5/J5,0)*M5*K5*(1+L5)) -> 35200 | U5: =IF(D5="demand",Q5*Assumptions!$B$17,ROUNDUP(O5/J5,0)*M5*K5*(1+L5)) -> 352000 | V5: =T5*F5 -> 352 | W5: =U5*F5 -> 3520 | X5: One page/query assumed; full coverage and pagination unverified. Shared union of followed keys for entity tools; one shared list for global tools. | Y5: Catalogue price/source
A6: T05 | B6: nasdaq | C6: /get_mutual_fund_quote | D6: entity | E6: entity_daily | F6: 0.01 | G6: 0 | H6: 5 | I6: 5 | J6: 1 | K6: 1 | L6: 0 | M6: =Profiles!D7 -> 30 | N6: =IF(H6>0,H6,IF(D6="entity",MAX(Assumptions!$B$7,ROUNDUP(Assumptions!$B$2*Assumptions!$B$7*Assumptions!$B$8,0)),1)) -> 5 | O6: =IF(I6>0,I6,IF(D6="entity",MAX(Assumptions!$B$7,ROUNDUP(Assumptions!$B$3*Assumptions!$B$7*Assumptions!$B$8,0)),1)) -> 5 | P6: =ROUNDUP(Assumptions!$B$2*Assumptions!$B$4*Assumptions!$B$5/J6,0)*K6*(1+L6) -> 1100 | Q6: =ROUNDUP(Assumptions!$B$3*Assumptions!$B$4*Assumptions!$B$5/J6,0)*K6*(1+L6) -> 11000 | R6: =P6*F6 -> 11 | S6: =Q6*F6 -> 110 | T6: =IF(D6="demand",P6*Assumptions!$B$17,ROUNDUP(N6/J6,0)*M6*K6*(1+L6)) -> 150 | U6: =IF(D6="demand",Q6*Assumptions!$B$17,ROUNDUP(O6/J6,0)*M6*K6*(1+L6)) -> 150 | V6: =T6*F6 -> 1.5 | W6: =U6*F6 -> 1.5 | X6: One page/query assumed; full coverage and pagination unverified. Fixed optional universe of 5 keys in both scenarios. | Y6: Catalogue price/source
A7: T06 | B7: nasdaq | C7: /get_stock_dividend_history | D7: entity | E7: entity_daily | F7: 0.01 | G7: 0 | H7: 0 | I7: 0 | J7: 1 | K7: 1 | L7: 0 | M7: =Profiles!D7 -> 30 | N7: =IF(H7>0,H7,IF(D7="entity",MAX(Assumptions!$B$7,ROUNDUP(Assumptions!$B$2*Assumptions!$B$7*Assumptions!$B$8,0)),1)) -> 100 | O7: =IF(I7>0,I7,IF(D7="entity",MAX(Assumptions!$B$7,ROUNDUP(Assumptions!$B$3*Assumptions!$B$7*Assumptions!$B$8,0)),1)) -> 1000 | P7: =ROUNDUP(Assumptions!$B$2*Assumptions!$B$4*Assumptions!$B$5/J7,0)*K7*(1+L7) -> 1100 | Q7: =ROUNDUP(Assumptions!$B$3*Assumptions!$B$4*Assumptions!$B$5/J7,0)*K7*(1+L7) -> 11000 | R7: =P7*F7 -> 11 | S7: =Q7*F7 -> 110 | T7: =IF(D7="demand",P7*Assumptions!$B$17,ROUNDUP(N7/J7,0)*M7*K7*(1+L7)) -> 3000 | U7: =IF(D7="demand",Q7*Assumptions!$B$17,ROUNDUP(O7/J7,0)*M7*K7*(1+L7)) -> 30000 | V7: =T7*F7 -> 30 | W7: =U7*F7 -> 300 | X7: One page/query assumed; full coverage and pagination unverified. Shared union of followed keys for entity tools; one shared list for global tools. | Y7: Catalogue price/source
A8: T07 | B8: nasdaq | C8: /get_stock_quote | D8: entity | E8: entity_market | F8: 0.01 | G8: 0 | H8: 0 | I8: 0 | J8: 1 | K8: 1 | L8: 0 | M8: =Profiles!D2 -> 1716 | N8: =IF(H8>0,H8,IF(D8="entity",MAX(Assumptions!$B$7,ROUNDUP(Assumptions!$B$2*Assumptions!$B$7*Assumptions!$B$8,0)),1)) -> 100 | O8: =IF(I8>0,I8,IF(D8="entity",MAX(Assumptions!$B$7,ROUNDUP(Assumptions!$B$3*Assumptions!$B$7*Assumptions!$B$8,0)),1)) -> 1000 | P8: =ROUNDUP(Assumptions!$B$2*Assumptions!$B$4*Assumptions!$B$5/J8,0)*K8*(1+L8) -> 1100 | Q8: =ROUNDUP(Assumptions!$B$3*Assumptions!$B$4*Assumptions!$B$5/J8,0)*K8*(1+L8) -> 11000 | R8: =P8*F8 -> 11 | S8: =Q8*F8 -> 110 | T8: =IF(D8="demand",P8*Assumptions!$B$17,ROUNDUP(N8/J8,0)*M8*K8*(1+L8)) -> 171600 | U8: =IF(D8="demand",Q8*Assumptions!$B$17,ROUNDUP(O8/J8,0)*M8*K8*(1+L8)) -> 1716000 | V8: =T8*F8 -> 1716 | W8: =U8*F8 -> 17160 | X8: One page/query assumed; full coverage and pagination unverified. Shared union of followed keys for entity tools; one shared list for global tools. | Y8: Catalogue price/source
A9: T08 | B9: nasdaq | C9: /search_symbols | D9: demand | E9: lookup_demand | F9: 0.01 | G9: 0 | H9: 0 | I9: 0 | J9: 1 | K9: 1 | L9: 0 | M9: =Profiles!D9 -> 0 | N9: =IF(H9>0,H9,IF(D9="entity",MAX(Assumptions!$B$7,ROUNDUP(Assumptions!$B$2*Assumptions!$B$7*Assumptions!$B$8,0)),1)) -> 1 | O9: =IF(I9>0,I9,IF(D9="entity",MAX(Assumptions!$B$7,ROUNDUP(Assumptions!$B$3*Assumptions!$B$7*Assumptions!$B$8,0)),1)) -> 1 | P9: =ROUNDUP(Assumptions!$B$2*Assumptions!$B$4*Assumptions!$B$5/J9,0)*K9*(1+L9) -> 1100 | Q9: =ROUNDUP(Assumptions!$B$3*Assumptions!$B$4*Assumptions!$B$5/J9,0)*K9*(1+L9) -> 11000 | R9: =P9*F9 -> 11 | S9: =Q9*F9 -> 110 | T9: =IF(D9="demand",P9*Assumptions!$B$17,ROUNDUP(N9/J9,0)*M9*K9*(1+L9)) -> 550 | U9: =IF(D9="demand",Q9*Assumptions!$B$17,ROUNDUP(O9/J9,0)*M9*K9*(1+L9)) -> 5500 | V9: =T9*F9 -> 5.5 | W9: =U9*F9 -> 55 | X9: One page/query assumed; full coverage and pagination unverified. Shared union of followed keys for entity tools; one shared list for global tools. | Y9: Catalogue price/source
A10: T09 | B10: nasdaq | C10: /get_market_indices | D10: global | E10: global_market | F10: 0.01 | G10: 0 | H10: 0 | I10: 0 | J10: 1 | K10: 1 | L10: 0 | M10: =Profiles!D3 -> 1716 | N10: =IF(H10>0,H10,IF(D10="entity",MAX(Assumptions!$B$7,ROUNDUP(Assumptions!$B$2*Assumptions!$B$7*Assumptions!$B$8,0)),1)) -> 1 | O10: =IF(I10>0,I10,IF(D10="entity",MAX(Assumptions!$B$7,ROUNDUP(Assumptions!$B$3*Assumptions!$B$7*Assumptions!$B$8,0)),1)) -> 1 | P10: =ROUNDUP(Assumptions!$B$2*Assumptions!$B$4*Assumptions!$B$5/J10,0)*K10*(1+L10) -> 1100 | Q10: =ROUNDUP(Assumptions!$B$3*Assumptions!$B$4*Assumptions!$B$5/J10,0)*K10*(1+L10) -> 11000 | R10: =P10*F10 -> 11 | S10: =Q10*F10 -> 110 | T10: =IF(D10="demand",P10*Assumptions!$B$17,ROUNDUP(N10/J10,0)*M10*K10*(1+L10)) -> 1716 | U10: =IF(D10="demand",Q10*Assumptions!$B$17,ROUNDUP(O10/J10,0)*M10*K10*(1+L10)) -> 1716 | V10: =T10*F10 -> 17.16 | W10: =U10*F10 -> 17.16 | X10: One page/query assumed; full coverage and pagination unverified. Shared union of followed keys for entity tools; one shared list for global tools. | Y10: Catalogue price/source
A11: T10 | B11: nasdaq | C11: /get_stock_historical_quotes | D11: entity | E11: entity_daily | F11: 0.01 | G11: 0 | H11: 0 | I11: 0 | J11: 1 | K11: 1 | L11: 0 | M11: =Profiles!D7 -> 30 | N11: =IF(H11>0,H11,IF(D11="entity",MAX(Assumptions!$B$7,ROUNDUP(Assumptions!$B$2*Assumptions!$B$7*Assumptions!$B$8,0)),1)) -> 100 | O11: =IF(I11>0,I11,IF(D11="entity",MAX(Assumptions!$B$7,ROUNDUP(Assumptions!$B$3*Assumptions!$B$7*Assumptions!$B$8,0)),1)) -> 1000 | P11: =ROUNDUP(Assumptions!$B$2*Assumptions!$B$4*Assumptions!$B$5/J11,0)*K11*(1+L11) -> 1100 | Q11: =ROUNDUP(Assumptions!$B$3*Assumptions!$B$4*Assumptions!$B$5/J11,0)*K11*(1+L11) -> 11000 | R11: =P11*F11 -> 11 | S11: =Q11*F11 -> 110 | T11: =IF(D11="demand",P11*Assumptions!$B$17,ROUNDUP(N11/J11,0)*M11*K11*(1+L11)) -> 3000 | U11: =IF(D11="demand",Q11*Assumptions!$B$17,ROUNDUP(O11/J11,0)*M11*K11*(1+L11)) -> 30000 | V11: =T11*F11 -> 30 | W11: =U11*F11 -> 300 | X11: One page/query assumed; full coverage and pagination unverified. Shared union of followed keys for entity tools; one shared list for global tools. | Y11: Catalogue price/source
A12: T11 | B12: nasdaq | C12: /get_stock_institutional_holdings | D12: entity | E12: entity_daily | F12: 0.01 | G12: 0 | H12: 0 | I12: 0 | J12: 1 | K12: 1 | L12: 0 | M12: =Profiles!D7 -> 30 | N12: =IF(H12>0,H12,IF(D12="entity",MAX(Assumptions!$B$7,ROUNDUP(Assumptions!$B$2*Assumptions!$B$7*Assumptions!$B$8,0)),1)) -> 100 | O12: =IF(I12>0,I12,IF(D12="entity",MAX(Assumptions!$B$7,ROUNDUP(Assumptions!$B$3*Assumptions!$B$7*Assumptions!$B$8,0)),1)) -> 1000 | P12: =ROUNDUP(Assumptions!$B$2*Assumptions!$B$4*Assumptions!$B$5/J12,0)*K12*(1+L12) -> 1100 | Q12: =ROUNDUP(Assumptions!$B$3*Assumptions!$B$4*Assumptions!$B$5/J12,0)*K12*(1+L12) -> 11000 | R12: =P12*F12 -> 11 | S12: =Q12*F12 -> 110 | T12: =IF(D12="demand",P12*Assumptions!$B$17,ROUNDUP(N12/J12,0)*M12*K12*(1+L12)) -> 3000 | U12: =IF(D12="demand",Q12*Assumptions!$B$17,ROUNDUP(O12/J12,0)*M12*K12*(1+L12)) -> 30000 | V12: =T12*F12 -> 30 | W12: =U12*F12 -> 300 | X12: One page/query assumed; full coverage and pagination unverified. Shared union of followed keys for entity tools; one shared list for global tools. | Y12: Catalogue price/source
A13: T12 | B13: nasdaq | C13: /get_market_movers | D13: global | E13: global_market | F13: 0.01 | G13: 0 | H13: 0 | I13: 0 | J13: 1 | K13: 1 | L13: 0 | M13: =Profiles!D3 -> 1716 | N13: =IF(H13>0,H13,IF(D13="entity",MAX(Assumptions!$B$7,ROUNDUP(Assumptions!$B$2*Assumptions!$B$7*Assumptions!$B$8,0)),1)) -> 1 | O13: =IF(I13>0,I13,IF(D13="entity",MAX(Assumptions!$B$7,ROUNDUP(Assumptions!$B$3*Assumptions!$B$7*Assumptions!$B$8,0)),1)) -> 1 | P13: =ROUNDUP(Assumptions!$B$2*Assumptions!$B$4*Assumptions!$B$5/J13,0)*K13*(1+L13) -> 1100 | Q13: =ROUNDUP(Assumptions!$B$3*Assumptions!$B$4*Assumptions!$B$5/J13,0)*K13*(1+L13) -> 11000 | R13: =P13*F13 -> 11 | S13: =Q13*F13 -> 110 | T13: =IF(D13="demand",P13*Assumptions!$B$17,ROUNDUP(N13/J13,0)*M13*K13*(1+L13)) -> 1716 | U13: =IF(D13="demand",Q13*Assumptions!$B$17,ROUNDUP(O13/J13,0)*M13*K13*(1+L13)) -> 1716 | V13: =T13*F13 -> 17.16 | W13: =U13*F13 -> 17.16 | X13: One page/query assumed; full coverage and pagination unverified. Shared union of followed keys for entity tools; one shared list for global tools. | Y13: Catalogue price/source
A14: T13 | B14: nasdaq | C14: /get_etf_quote | D14: entity | E14: entity_market | F14: 0.01 | G14: 0 | H14: 5 | I14: 5 | J14: 1 | K14: 1 | L14: 0 | M14: =Profiles!D2 -> 1716 | N14: =IF(H14>0,H14,IF(D14="entity",MAX(Assumptions!$B$7,ROUNDUP(Assumptions!$B$2*Assumptions!$B$7*Assumptions!$B$8,0)),1)) -> 5 | O14: =IF(I14>0,I14,IF(D14="entity",MAX(Assumptions!$B$7,ROUNDUP(Assumptions!$B$3*Assumptions!$B$7*Assumptions!$B$8,0)),1)) -> 5 | P14: =ROUNDUP(Assumptions!$B$2*Assumptions!$B$4*Assumptions!$B$5/J14,0)*K14*(1+L14) -> 1100 | Q14: =ROUNDUP(Assumptions!$B$3*Assumptions!$B$4*Assumptions!$B$5/J14,0)*K14*(1+L14) -> 11000 | R14: =P14*F14 -> 11 | S14: =Q14*F14 -> 110 | T14: =IF(D14="demand",P14*Assumptions!$B$17,ROUNDUP(N14/J14,0)*M14*K14*(1+L14)) -> 8580 | U14: =IF(D14="demand",Q14*Assumptions!$B$17,ROUNDUP(O14/J14,0)*M14*K14*(1+L14)) -> 8580 | V14: =T14*F14 -> 85.8 | W14: =U14*F14 -> 85.8 | X14: One page/query assumed; full coverage and pagination unverified. Fixed optional universe of 5 keys in both scenarios. | Y14: Catalogue price/source
A15: T14 | B15: nasdaq | C15: /get_cryptocurrency_quote | D15: entity | E15: entity_crypto | F15: 0.01 | G15: 0 | H15: 2 | I15: 2 | J15: 1 | K15: 1 | L15: 0 | M15: =Profiles!D10 -> 8640 | N15: =IF(H15>0,H15,IF(D15="entity",MAX(Assumptions!$B$7,ROUNDUP(Assumptions!$B$2*Assumptions!$B$7*Assumptions!$B$8,0)),1)) -> 2 | O15: =IF(I15>0,I15,IF(D15="entity",MAX(Assumptions!$B$7,ROUNDUP(Assumptions!$B$3*Assumptions!$B$7*Assumptions!$B$8,0)),1)) -> 2 | P15: =ROUNDUP(Assumptions!$B$2*Assumptions!$B$4*Assumptions!$B$5/J15,0)*K15*(1+L15) -> 1100 | Q15: =ROUNDUP(Assumptions!$B$3*Assumptions!$B$4*Assumptions!$B$5/J15,0)*K15*(1+L15) -> 11000 | R15: =P15*F15 -> 11 | S15: =Q15*F15 -> 110 | T15: =IF(D15="demand",P15*Assumptions!$B$17,ROUNDUP(N15/J15,0)*M15*K15*(1+L15)) -> 17280 | U15: =IF(D15="demand",Q15*Assumptions!$B$17,ROUNDUP(O15/J15,0)*M15*K15*(1+L15)) -> 17280 | V15: =T15*F15 -> 172.8 | W15: =U15*F15 -> 172.8 | X15: One page/query assumed; full coverage and pagination unverified. Fixed optional universe of 2 keys in both scenarios. | Y15: Catalogue price/source
A16: T15 | B16: nasdaq | C16: /get_stock_news | D16: entity | E16: entity_news | F16: 0.01 | G16: 0 | H16: 0 | I16: 0 | J16: 1 | K16: 1 | L16: 0 | M16: =Profiles!D4 -> 480 | N16: =IF(H16>0,H16,IF(D16="entity",MAX(Assumptions!$B$7,ROUNDUP(Assumptions!$B$2*Assumptions!$B$7*Assumptions!$B$8,0)),1)) -> 100 | O16: =IF(I16>0,I16,IF(D16="entity",MAX(Assumptions!$B$7,ROUNDUP(Assumptions!$B$3*Assumptions!$B$7*Assumptions!$B$8,0)),1)) -> 1000 | P16: =ROUNDUP(Assumptions!$B$2*Assumptions!$B$4*Assumptions!$B$5/J16,0)*K16*(1+L16) -> 1100 | Q16: =ROUNDUP(Assumptions!$B$3*Assumptions!$B$4*Assumptions!$B$5/J16,0)*K16*(1+L16) -> 11000 | R16: =P16*F16 -> 11 | S16: =Q16*F16 -> 110 | T16: =IF(D16="demand",P16*Assumptions!$B$17,ROUNDUP(N16/J16,0)*M16*K16*(1+L16)) -> 48000 | U16: =IF(D16="demand",Q16*Assumptions!$B$17,ROUNDUP(O16/J16,0)*M16*K16*(1+L16)) -> 480000 | V16: =T16*F16 -> 480 | W16: =U16*F16 -> 4800 | X16: One page/query assumed; full coverage and pagination unverified. Shared union of followed keys for entity tools; one shared list for global tools. | Y16: Catalogue price/source
A17: T16 | B17: nasdaq | C17: /get_stock_financials | D17: entity | E17: entity_daily | F17: 0.01 | G17: 0 | H17: 0 | I17: 0 | J17: 1 | K17: 1 | L17: 0 | M17: =Profiles!D7 -> 30 | N17: =IF(H17>0,H17,IF(D17="entity",MAX(Assumptions!$B$7,ROUNDUP(Assumptions!$B$2*Assumptions!$B$7*Assumptions!$B$8,0)),1)) -> 100 | O17: =IF(I17>0,I17,IF(D17="entity",MAX(Assumptions!$B$7,ROUNDUP(Assumptions!$B$3*Assumptions!$B$7*Assumptions!$B$8,0)),1)) -> 1000 | P17: =ROUNDUP(Assumptions!$B$2*Assumptions!$B$4*Assumptions!$B$5/J17,0)*K17*(1+L17) -> 1100 | Q17: =ROUNDUP(Assumptions!$B$3*Assumptions!$B$4*Assumptions!$B$5/J17,0)*K17*(1+L17) -> 11000 | R17: =P17*F17 -> 11 | S17: =Q17*F17 -> 110 | T17: =IF(D17="demand",P17*Assumptions!$B$17,ROUNDUP(N17/J17,0)*M17*K17*(1+L17)) -> 3000 | U17: =IF(D17="demand",Q17*Assumptions!$B$17,ROUNDUP(O17/J17,0)*M17*K17*(1+L17)) -> 30000 | V17: =T17*F17 -> 30 | W17: =U17*F17 -> 300 | X17: One page/query assumed; full coverage and pagination unverified. Shared union of followed keys for entity tools; one shared list for global tools. | Y17: Catalogue price/source
A18: T17 | B18: nasdaq | C18: /get_index_detail | D18: entity | E18: entity_market | F18: 0.01 | G18: 0 | H18: 5 | I18: 5 | J18: 1 | K18: 1 | L18: 0 | M18: =Profiles!D2 -> 1716 | N18: =IF(H18>0,H18,IF(D18="entity",MAX(Assumptions!$B$7,ROUNDUP(Assumptions!$B$2*Assumptions!$B$7*Assumptions!$B$8,0)),1)) -> 5 | O18: =IF(I18>0,I18,IF(D18="entity",MAX(Assumptions!$B$7,ROUNDUP(Assumptions!$B$3*Assumptions!$B$7*Assumptions!$B$8,0)),1)) -> 5 | P18: =ROUNDUP(Assumptions!$B$2*Assumptions!$B$4*Assumptions!$B$5/J18,0)*K18*(1+L18) -> 1100 | Q18: =ROUNDUP(Assumptions!$B$3*Assumptions!$B$4*Assumptions!$B$5/J18,0)*K18*(1+L18) -> 11000 | R18: =P18*F18 -> 11 | S18: =Q18*F18 -> 110 | T18: =IF(D18="demand",P18*Assumptions!$B$17,ROUNDUP(N18/J18,0)*M18*K18*(1+L18)) -> 8580 | U18: =IF(D18="demand",Q18*Assumptions!$B$17,ROUNDUP(O18/J18,0)*M18*K18*(1+L18)) -> 8580 | V18: =T18*F18 -> 85.8 | W18: =U18*F18 -> 85.8 | X18: One page/query assumed; full coverage and pagination unverified. Fixed optional universe of 5 keys in both scenarios. | Y18: Catalogue price/source
